Workbook
Name Connection_Type: #REF!
Name Connection_Type: 'Drill Size Info'!$C$2:$C$49
Name Contractor_Name: #REF!
Name Contractor_Name: 'Contractor-Operator'!$C$2:$C$19
Name DynPrint_DP: OFFSET(#REF!,1,1,COUNTA(#REF!),48)
Name DynPrint_DP: OFFSET('Prop Drill Pipe Inp Report'!$A$1,1,1,COUNTA('Prop Drill Pipe Inp Report'!$F$2:$F99999),48)
Name DynPrint_HWDP: OFFSET(#REF!,1,1,COUNTA(#REF!),48)
Name DynPrint_HWDP: OFFSET('Prop Subs Inp Report'!$A$1,1,1,COUNTA('Prop Subs Inp Report'!$B$2:$C9999),48)
Name DynPrint_HWDP: OFFSET('Prop HWDP Inp Report'!$A$1,1,1,COUNTA('Prop HWDP Inp Report'!$B$2:$C9999),48)
Name DynPrint_Subs: OFFSET(#REF!,1,1,COUNTA(#REF!),48)
Name Grade: #REF!
Name Grade: 'Summary Drill Pipe'!$E$8
Name Machine_Shop: #REF!
Name Machine_Shop: 'Shop List'!$A$2:$A$12
Name Operator_Name: #REF!
Name Operator_Name: 'Contractor-Operator'!$A$2:$A$100
Name Size: #REF!
Name Size: 'Summary Drill Pipe'!$A$8
Name UT_Thickness: #REF!
Name UT_Thickness: 'Prop Drill Pipe Inp Report'!$F$9:$F$1048576
Name Weight: 'Summary Drill Pipe'!$B$8

Sheet DATA SHEET
P1: Save a copy before typing
A2: Operator: | D2: DRILL PIPE INSPECTION | G2: Reface
A3: Contractor: | D3: CATEGORY | E3: Cat 4 | G3: Cat 2 | I3: TH-Hill DS-1 Vol 3 CAT 2 - 5th Edition: Clean and Visual Ends only | P3: Please Don’t Delete Any Tabs
A4: Rig Number: | G4: Cat 2 w/Blacklight | I4: TH-Hill DS-1 Vol 3 CAT 2 - 5th Edition: Clean and Visual Ends w/MPI Blacklight
A5: Date: | D5: ADDITIONAL | E5: , Actual OD's, ID's, and Tong Space | G5: Cat 3 | I5: TH-Hill DS-1 Vol 3 CAT 3 - 5th Edition: Clean and Visual Ends w/EMI of Tubes | P5: Refacing options available under Category
A6: Field Invoice: | G6: Cat 3-5 | I6: TH-Hill DS-1 Vol 3 CAT 3-5 - 5th Edition: Clean and Visual Ends w/Buff and Powder
A7: Inspection Crew: | D7: ADDITIONAL | G7: Cat 4 | I7: TH-Hill DS-1 Vol 3 CAT 4 - 5th Edition: Clean and Visual Ends | P7: If connection type not on list leave in blank cell under grade
G8: Cat 4 w/Blacklight | I8: TH-Hill DS-1 Vol 3 CAT 4 - 5th Edition: Clean and Visual Ends w/Blacklight
A9: Connection Size | D9: HWDP INSPECTION | G9: Cat 5 | I9: TH-Hill DS-1 Vol 3 CAT 5 - 5th Edition: Clean and Visual Ends
A10: Connection Type: | D10: CATEGORY | G10: API RP 7G | I10: API RP 7G
A11: Grade | G11: Lathe reface
D12: ADDITIONAL | G12: , Actual OD's, ID's, and Tong Space
A13: State | G13: Excluding Bevel Diameter
D14: ADDITIONAL
D16: SUBS INSPECTION
D17: CATEGORY
D19: ADDITIONAL
D21: ADDITIONAL

Sheet Drill Size Info
A1: Connection | B1: Min OD | C1: Max ID | D1: Box Tong | E1: Pin Tong | F1: Box CL Min | G1: Box CL Max | H1: Pin CL Min | I1: Pin CL Max | J1: Reface | K1: API, Propriatary, Lathe | T1: SIZE | U1: WT | W1: WEIGHT | X1: GRADE
A2: 4.5 IF | B2: 6.3125 | C2: 3.40625 | D2: 6.125 | E2: 4.71875 | J2: In Field | K2: API | P2: " HWDP | T2: 4 | U2: 0.33 | V2: =0.8*U2 -> 0.264 | W2: 14 | X2: E-75
A3: 4.5 XH | B3: 5.78125 | C3: 3.15625 | D3: 6.125 | E3: 4.34375 | J3: In Field | T3: 4.5 | U3: 0.337 | V3: =0.8*U3 -> 0.2696 | W3: 16.6 | X3: X-95
A4: 4.5 XO | J4: In Field | T4: 4.75 | U4: 0.35 | V4: =0.8*U4 -> 0.28 | W4: 19.2 | X4: G-105
A5: 5.5 FH | B5: 6.75 | C5: 4.25 | D5: 6.625 | E5: 5.046875 | J5: In Field | T5: 5 | U5: 0.362 | V5: =0.8*U5 -> 0.2896 | W5: 19.5 | X5: S-135
A6: CET 43 | B6: 5.117 | C6: 3.063 | D6: 6 | E6: 6 | F6: 4.495 | G6: 4.509 | H6: 4.492 | I6: 4.505 | J6: In Field | K6: P | T6: 5.25 | U6: 0.362 | V6: =0.8*U6 -> 0.2896 | X6: V-150
A7: CET 50 | B7: 5.95 | C7: 3.813 | D7: 6 | E7: 6 | F7: 4.495 | G7: 4.509 | H7: 4.492 | I7: 4.505 | J7: In Field | K7: p | T7: 5.5 | U7: 0.361 | V7: =0.8*U7 -> 0.2888 | W7: 21.9
A8: Delta 391 | B8: 4.575 | C8: 2.688 | D8: 6.5 | E8: 6 | F8: 4.436 | G8: 4.443 | H8: 4.429 | I8: 4.438 | J8: In Field | K8: P | T8: 5.5 | U8: 0.415 | V8: =0.8*U8 -> 0.332 | W8: 24.7
A9: Delta 425 | B9: 4.983 | C9: 3 | D9: 6.5 | E9: 6 | F9: 4.561 | G9: 4.568 | H9: 4.554 | I9: 4.563 | J9: In Field
A10: Delta 544 | B10: 6.232 | C10: 4 | D10: 6.5 | E10: 6 | F10: 5.123 | G10: 5.13 | H10: 5.116 | I10: 5.125 | J10: In Field Lathe
A11: DS 38 | B11: 4.57 | C11: 2.438 | D11: 6.5 | E11: 6 | F11: 4.402 | G11: 4.413 | H11: 4.396 | I11: 4.407 | J11: In Field
A12: DS 40 | B12: 4.836 | C12: 2.438 | D12: 6.5 | E12: 6 | F12: 4.915 | G12: 4.927 | H12: 4.907 | I12: 4.918 | J12: In Field | K12: P
A13: DS 42 | B13: 5.145 | C13: 2.75 | D13: 6.5 | E13: 6 | F13: 4.749 | G13: 4.76 | H13: 4.744 | I13: 4.755 | J13: In Field
A14: DS 50 | B14: 5.93 | C14: 3.25 | D14: 6.5 | E14: 6 | F14: 4.915 | G14: 4.927 | H14: 4.907 | I14: 4.918
A15: DS 55 | B15: 6.611 | C15: 4 | D15: 6.5 | E15: 6 | F15: 5.426 | G15: 5.437 | H15: 5.42 | I15: 5.431 | J15: In Field Lathe | K15: L
A16: UGPDS 55 | B16: 6.532 | C16: 4 | D16: 6.5 | E16: 6 | F16: 5.426 | G16: 5.437 | H16: 5.42 | I16: 5.431 | J16: In Field Lathe | K16: L
A17: Everdrill 46 | J17: Machine Shop | K17: L
A18: Everdrill 49 | J18: Machine Shop | K18: L
A19: Everdrill 54 | J19: Machine Shop | K19: L
A20: NC-46 | J20: In Field | K20: API
A21: NC-56 | J21: Machine Shop | K21: API
A22: NC-50 | B22: 6.3125 | C22: 3.40625 | D22: 6.125 | E22: 4.71875 | J22: In Field | K22: API
A23: Ptech-43 | B23: 4.969 | C23: 3.25 | D23: 6.5 | E23: 6.5 | F23: 4.455 | G23: 4.465 | H23: 4.446 | I23: 4.455
A24: Ptech-39 | B24: 4.531 | C24: 2.7035 | D24: 6.125 | E24: 6.125 | F24: 4.125 | G24: 4.135 | H24: 4.116 | I24: 4.125 | J24: In Field Lathe | K24: L
A25: Ptech-43 | J25: In Field Lathe | K25: L
A26: Ptech-55 | B26: 6.141 | C26: 4.25 | D26: 6.625 | E26: 6.625 | F26: 4.65 | G26: 4.66 | H26: 4.641 | I26: 4.65 | J26: In Field Lathe | K26: L
A27: XT-39 | B27: 4.653 | C27: 2.563 | D27: 8 | E27: 6 | F27: 4.498 | G27: 4.503 | H27: 4.491 | I27: 4.5 | J27: In Field | K27: P
A28: XT-50 | B28: 6.065 | C28: 3.75 | D28: 8.31 | E28: 6 | F28: 7.305 | G28: 7.31 | H28: 7.291 | I28: 7.3
A29: XT-54 | B29: 6.313 | C29: 4 | D29: 8.01 | E29: 6 | F29: 7.005 | G29: 7.01 | H29: 6.991 | I29: 7 | J29: In Field | K29: P
A30: AOH
A31: HLNST 54
A32: Delta 471
A33: CET 54

Sheet Summary Drill Pipe
A1: Operator: | C1: ='DATA SHEET'!B2 -> 0 | F1: ='DATA SHEET'!$B$13 -> 0
A2: Contractor: | C2: =CONCATENATE('DATA SHEET'!B3," ",'DATA SHEET'!B4)
A3: Date: | C3: ='DATA SHEET'!B5 -> 0
A4: Field Invoice: | C4: ='DATA SHEET'!B6 -> 0
A5: Inspection Crew: | C5: ='DATA SHEET'!B7 -> 0
A6: Inspection Type | C6: =IFERROR(CONCATENATE(VLOOKUP('DATA SHEET'!$E$3,'DATA SHEET'!$G$3:$I$10,3,FALSE),'DATA SHEET'!$E$5, 'DATA SHEET'!$E$7),"") -> TH-Hill DS-1 Vol 3 CAT 4 - 5th Edition: Clean and Visual Ends, Actual OD's, ID's, and Tong Space
A7: Size | B7: Weight | C7: Connection Type | E7: Grade
A8: ='DATA SHEET'!B9 -> 0 | B8: =VLOOKUP(A8,'Drill Size Info'!$T$2:$W$7,4,FALSE) -> #N/A | C8: ='DATA SHEET'!B10 -> 0 | E8: ='DATA SHEET'!B11 -> 0
A10: Machine Shop | C10: Contact | D10: Number
A11: N/A | C11: =VLOOKUP($A$11,'Shop List'!$A$2:$D$9,3,FALSE) -> N/A | D11: =VLOOKUP($A$11,'Shop List'!$A$2:$D$9,4,FALSE) -> N/A | L11: Drill Pipe
A14: Inspection Summary
A15: Premium: | C15: =J15-C17 -> 0 | H15: Joints Inspected: | J15: =COUNTA('Prop Drill Pipe Inp Report'!F9:F1048576) -> 0
D16: Max Calculated Tensile Load | G16: =IF(Grade="S-135",135*(PI()*((Size/2)^2-((Size/2)-MIN(UT_Thickness))^2)),IF(Grade="G-105",105*(PI()*((Size/2)^2-((Size/2)-MIN(UT_Thickness))^2)),IF(Grade="X-95",95*(PI()*((Size/2)^2-((Size/2)-MIN(UT_Thickness))^2)),IF(Grade="V-150",150*(PI()*((Size/2)^2-((Size/2)-MIN(UT_Thickness))^2)),IF(Grade="E-75",75*(PI()*((Size/2)^2-((Size/2)-MIN(UT_Thickness))^2)))))))*1000 -> 0 | H16: Joints Rig Ready: | J16: =J15-J17-C17 -> 0
A17: DBR: | C17: =SUMIF('Data Sheet DP'!J2:J2500,"<>#REF!") -> 0 | H17: Joints to Machine Shop: | J17: =SUMIF('Data Sheet DP'!I2:I2500,"<>#REF!") -> 0
A19: Field Repair | F19: Total Hardbands: | G19: =SUM(I20:K20) -> 0 | I19: Box | K19: Pin
A20: Refaces: | I20: ='Prop Drill Pipe Inp Report'!AU7 -> 0 | K20: ='Prop Drill Pipe Inp Report'!AX7 -> 0
A21: Box: | D21: Pin: | F21: Damaged Hardband: | G21: =SUM(I22:K22) -> 0 | I21: Box: | K21: Pin:
A22: ='Prop Drill Pipe Inp Report'!Z7 -> 0 | D22: ='Prop Drill Pipe Inp Report'!AB7 -> 0 | I22: ='Prop Drill Pipe Inp Report'!AS7 -> 0 | K22: ='Prop Drill Pipe Inp Report'!AT7 -> 0
A23: Pin Nose Repair: | D23: 0 | F23: DBR Hardband: | G23: =SUM(I24:K24) -> 0 | I23: Box: | K23: Pin:
I24: ='Prop Drill Pipe Inp Report'!AY7 -> 0 | K24: ='Prop Drill Pipe Inp Report'!AZ7 -> 0
A54: Remarks:

Sheet Prop Drill Pipe Inp Report
B2: Operator: | F2: ='DATA SHEET'!B2 -> 0 | AD2: Pathfinder Inspections and Field Services LLC
B3: Rig Name & Number: | F3: ='Summary Drill Pipe'!C2 | H3: Field Invoice: | K3: ='Summary Drill Pipe'!C4 -> 0 | AD3: Physical Address | AJ3: 7501 Groening Street, Odessa TX 79765 | BY3: need to insert dimensions from DS-1 like our inspection reports
B4: Date: | F4: ='Summary Drill Pipe'!C3 -> 0 | H4: Inspector/Crew: | K4: ='Summary Drill Pipe'!C5 -> 0 | AD4: Mailing Address | AJ4: PO Box 3889, Gillette, WY 82717
B5: Connection: | D5: ='Summary Drill Pipe'!C8 -> 0 | F5: Size: | G5: =Size -> 0 | H5: Grade | K5: ='Summary Drill Pipe'!E8 -> 0 | AD5: Contact Info | AJ5: Jana Streitz - Owner, (C) 406-579-2672
D6: Dimensional | Z6: Refaces | AD6: Damages
B7: Identification | D7: Tube | H7: Tool Joint | J7: Bevel Dia. | L7: Tong Spa. | Z7: =COUNTA(Z9:Z1008) -> 0 | AB7: =COUNTA(AB9:AB1008) -> 0 | AD7: =COUNTA(AD9:AD1008) -> 0 | AE7: =COUNTA(AE9:AE1008) -> 0 | AF7: =COUNTA(AF9:AF1008) -> 0 | AG7: =COUNTA(AG9:AG1008) -> 0 | AH7: =COUNTA(AH9:AH1008) -> 0 | AI7: =COUNTA(AI9:AI1008) -> 0 | AJ7: =COUNTA(AJ9:AJ1008) -> 0 | AK7: =COUNTA(AK9:AK1008) -> 0 | ... BM7: =COUNTA(BM9:BM1008) -> 0 | BZ7: =SUM(BZ9:BZ872) -> 0 | CA7: =SUM(CA9:CA872) -> 0 | CB7: =SUM(CB9:CB872) -> 0 | CC7: =SUM(CC9:CC872) -> 0 | CD7: =SUM(CD9:CD872) -> 0 | CE7: =SUM(CE9:CE872) -> 0 | CF7: =SUM(CF9:CF872) -> 0 | CG7: =SUM(CG9:CG872) -> 0 | ... DK7: =SUM(DK9:DK872) -> 0
B8: Joint #: | C8: Serial #: | D8: OD Gage: | E8: Nominal Wall Thickness: | F8: UT Thickness: | G8: % of Nom Wall: | H8: Box OD: | I8: Pin ID: | J8: Box: | K8: Pin: | L8: Box: | M8: Pin: | N8: Boreback Dia: | O8: Boreback Length: | P8: Stress Relief Groove Diameter: | Q8: Stress Relief Groove Length: | R8: C"Bore Depth: | S8: C"Bore Dia: | T8: Seal Width: | U8: Pin Nose Diameter: | V8: Box Critical Length: | W8: Length After Repair: | X8: Pin Critical Length: | Y8: Length After Repair: | Z8: Box Reface | AA8: Reface Type Box: | AB8: Pin Reface | AC8: Reface Type Pin: | AD8: Damaged Seal Box: | AE8: Damaged Seal Pin: | AF8: Damaged Threads Box: | AG8: Damaged Threads Pin: | AH8: Damaged Torque Shoulder Box: | AI8: Damaged Torque Shoulder Pin: | AJ8: Pitted Box: | AK8: Pitted Pin: | AL8: Over Refaced Box: | AM8: Over Refaced Pin: | AN8: Bent Tube: | AO8: Other Damage: | AP8: Other Damage: | AQ8: Other Damage: | AR8: Other Damage: | AS8: Damaged Hardband Box: | AT8: Damaged Hardband Pin: | AU8: Hardband Box: | AV8: Hardband Centerpad #1: | AW8: Hardband Centerpad #2: | AX8: Hardband Pin: | AY8: DBR Hardband Box: | AZ8: DBR Hardband Pin: | BA8: Minimum Wall Tube: | BB8: Min Tong Box: | BC8: Min Tong Pin: | BD8: Min Seal Box: | BE8: Min Seal Pin: | BF8: Minimum OD: | BG8: Damaged Tube: | BH8: EMI Reject: | BI8: Other: | BJ8: Box - Thread Recondition: | BK8: Pin - Thread Recondition: | BL8: Box - Bevel Repair: | BM8: Pin - Bevel Repair: | BP8: Letters | BQ8: Numbers | BR8: Letters | BS8: Numbers | BZ8: =Z8 -> Box Reface | CA8: =AB8 -> Pin Reface | CB8: =AD8 -> Damaged Seal Box: | CC8: =AE8 -> Damaged Seal Pin: | CD8: =AF8 -> Damaged Threads Box: | CE8: =AG8 -> Damaged Threads Pin: | CF8: =AH8 -> Damaged Torque Shoulder Box: | CG8: =AI8 -> Damaged Torque Shoulder Pin: | CH8: =AJ8 -> Pitted Box: | CI8: =AK8 -> Pitted Pin: | ... DK8: =BM8 -> Pin - Bevel Repair:
B9: 1 | BT9: =CONCATENATE(BP9,BQ9,BR9,BS9) | BZ9: =IF(Z9="x",1,0) -> 0 | CA9: =IF(AB9="x",1,0) -> 0 | CB9: =IF(AD9="x",1,0) -> 0 | CC9: =IF(AE9="x",1,0) -> 0 | CD9: =IF(AF9="x",1,0) -> 0 | CE9: =IF(AG9="x",1,0) -> 0 | CF9: =IF(AH9="x",1,0) -> 0 | CG9: =IF(AI9="x",1,0) -> 0 | CH9: =IF(AJ9="x",1,0) -> 0 | CI9: =IF(AK9="x",1,0) -> 0 | ... DK9: =IF(BM9="x",1,0) -> 0 | DL9: {=Z9:BI9} -> 0 | DM9: 0 | DN9: 0 | DO9: 0 | DP9: 0 | DQ9: 0 | DR9: 0 | DS9: 0 | DT9: 0 | DU9: 0 | DV9: 0 | DW9: 0 | DX9: 0 | DY9: 0 | DZ9: 0 | EA9: 0 | EB9: 0 | EC9: 0 | ED9: 0 | EE9: 0 | EF9: 0 | EG9: 0 | EH9: 0 | EI9: 0 | EJ9: 0 | EK9: 0 | EL9: 0 | EM9: 0 | EN9: 0 | EO9: 0 | EP9: 0 | EQ9: 0 | ER9: 0 | ES9: 0 | ET9: 0 | EU9: 0
B10: 2 | BT10: =CONCATENATE(BP10,BQ10,BR10,BS10) | BZ10: =IF(Z10="x",1,0) -> 0 | CA10: =IF(AB10="x",1,0) -> 0 | CB10: =IF(AD10="x",1,0) -> 0 | CC10: =IF(AE10="x",1,0) -> 0 | CD10: =IF(AF10="x",1,0) -> 0 | CE10: =IF(AG10="x",1,0) -> 0 | CF10: =IF(AH10="x",1,0) -> 0 | CG10: =IF(AI10="x",1,0) -> 0 | CH10: =IF(AJ10="x",1,0) -> 0 | CI10: =IF(AK10="x",1,0) -> 0 | ... DK10: =IF(BM10="x",1,0) -> 0
B11: 3 | BT11: =CONCATENATE(BP11,BQ11,BR11,BS11) | BZ11: =IF(Z11="x",1,0) -> 0 | CA11: =IF(AB11="x",1,0) -> 0 | CB11: =IF(AD11="x",1,0) -> 0 | CC11: =IF(AE11="x",1,0) -> 0 | CD11: =IF(AF11="x",1,0) -> 0 | CE11: =IF(AG11="x",1,0) -> 0 | CF11: =IF(AH11="x",1,0) -> 0 | CG11: =IF(AI11="x",1,0) -> 0 | CH11: =IF(AJ11="x",1,0) -> 0 | CI11: =IF(AK11="x",1,0) -> 0 | ... DK11: =IF(BM11="x",1,0) -> 0
B12: 4 | BT12: =CONCATENATE(BP12,BQ12,BR12,BS12) | BZ12: =IF(Z12="x",1,0) -> 0 | CA12: =IF(AB12="x",1,0) -> 0 | CB12: =IF(AD12="x",1,0) -> 0 | CC12: =IF(AE12="x",1,0) -> 0 | CD12: =IF(AF12="x",1,0) -> 0 | CE12: =IF(AG12="x",1,0) -> 0 | CF12: =IF(AH12="x",1,0) -> 0 | CG12: =IF(AI12="x",1,0) -> 0 | CH12: =IF(AJ12="x",1,0) -> 0 | CI12: =IF(AK12="x",1,0) -> 0 | ... DK12: =IF(BM12="x",1,0) -> 0
B13: 5 | BT13: =CONCATENATE(BP13,BQ13,BR13,BS13) | BZ13: =IF(Z13="x",1,0) -> 0 | CA13: =IF(AB13="x",1,0) -> 0 | CB13: =IF(AD13="x",1,0) -> 0 | CC13: =IF(AE13="x",1,0) -> 0 | CD13: =IF(AF13="x",1,0) -> 0 | CE13: =IF(AG13="x",1,0) -> 0 | CF13: =IF(AH13="x",1,0) -> 0 | CG13: =IF(AI13="x",1,0) -> 0 | CH13: =IF(AJ13="x",1,0) -> 0 | CI13: =IF(AK13="x",1,0) -> 0 | ... DK13: =IF(BM13="x",1,0) -> 0
B14: 6 | BT14: =CONCATENATE(BP14,BQ14,BR14,BS14) | BZ14: =IF(Z14="x",1,0) -> 0 | CA14: =IF(AB14="x",1,0) -> 0 | CB14: =IF(AD14="x",1,0) -> 0 | CC14: =IF(AE14="x",1,0) -> 0 | CD14: =IF(AF14="x",1,0) -> 0 | CE14: =IF(AG14="x",1,0) -> 0 | CF14: =IF(AH14="x",1,0) -> 0 | CG14: =IF(AI14="x",1,0) -> 0 | CH14: =IF(AJ14="x",1,0) -> 0 | CI14: =IF(AK14="x",1,0) -> 0 | ... DK14: =IF(BM14="x",1,0) -> 0
B15: 7 | BT15: =CONCATENATE(BP15,BQ15,BR15,BS15) | BZ15: =IF(Z15="x",1,0) -> 0 | CA15: =IF(AB15="x",1,0) -> 0 | CB15: =IF(AD15="x",1,0) -> 0 | CC15: =IF(AE15="x",1,0) -> 0 | CD15: =IF(AF15="x",1,0) -> 0 | CE15: =IF(AG15="x",1,0) -> 0 | CF15: =IF(AH15="x",1,0) -> 0 | CG15: =IF(AI15="x",1,0) -> 0 | CH15: =IF(AJ15="x",1,0) -> 0 | CI15: =IF(AK15="x",1,0) -> 0 | ... DK15: =IF(BM15="x",1,0) -> 0
B16: 8 | BT16: =CONCATENATE(BP16,BQ16,BR16,BS16) | BZ16: =IF(Z16="x",1,0) -> 0 | CA16: =IF(AB16="x",1,0) -> 0 | CB16: =IF(AD16="x",1,0) -> 0 | CC16: =IF(AE16="x",1,0) -> 0 | CD16: =IF(AF16="x",1,0) -> 0 | CE16: =IF(AG16="x",1,0) -> 0 | CF16: =IF(AH16="x",1,0) -> 0 | CG16: =IF(AI16="x",1,0) -> 0 | CH16: =IF(AJ16="x",1,0) -> 0 | CI16: =IF(AK16="x",1,0) -> 0 | ... DK16: =IF(BM16="x",1,0) -> 0
B17: 9 | BT17: =CONCATENATE(BP17,BQ17,BR17,BS17) | BZ17: =IF(Z17="x",1,0) -> 0 | CA17: =IF(AB17="x",1,0) -> 0 | CB17: =IF(AD17="x",1,0) -> 0 | CC17: =IF(AE17="x",1,0) -> 0 | CD17: =IF(AF17="x",1,0) -> 0 | CE17: =IF(AG17="x",1,0) -> 0 | CF17: =IF(AH17="x",1,0) -> 0 | CG17: =IF(AI17="x",1,0) -> 0 | CH17: =IF(AJ17="x",1,0) -> 0 | CI17: =IF(AK17="x",1,0) -> 0 | ... DK17: =IF(BM17="x",1,0) -> 0
B18: 10 | BT18: =CONCATENATE(BP18,BQ18,BR18,BS18) | BZ18: =IF(Z18="x",1,0) -> 0 | CA18: =IF(AB18="x",1,0) -> 0 | CB18: =IF(AD18="x",1,0) -> 0 | CC18: =IF(AE18="x",1,0) -> 0 | CD18: =IF(AF18="x",1,0) -> 0 | CE18: =IF(AG18="x",1,0) -> 0 | CF18: =IF(AH18="x",1,0) -> 0 | CG18: =IF(AI18="x",1,0) -> 0 | CH18: =IF(AJ18="x",1,0) -> 0 | CI18: =IF(AK18="x",1,0) -> 0 | ... DK18: =IF(BM18="x",1,0) -> 0
B19: 11 | BT19: =CONCATENATE(BP19,BQ19,BR19,BS19) | BZ19: =IF(Z19="x",1,0) -> 0 | CA19: =IF(AB19="x",1,0) -> 0 | CB19: =IF(AD19="x",1,0) -> 0 | CC19: =IF(AE19="x",1,0) -> 0 | CD19: =IF(AF19="x",1,0) -> 0 | CE19: =IF(AG19="x",1,0) -> 0 | CF19: =IF(AH19="x",1,0) -> 0 | CG19: =IF(AI19="x",1,0) -> 0 | CH19: =IF(AJ19="x",1,0) -> 0 | CI19: =IF(AK19="x",1,0) -> 0 | ... DK19: =IF(BM19="x",1,0) -> 0
B20: 12 | BT20: =CONCATENATE(BP20,BQ20,BR20,BS20) | BZ20: =IF(Z20="x",1,0) -> 0 | CA20: =IF(AB20="x",1,0) -> 0 | CB20: =IF(AD20="x",1,0) -> 0 | CC20: =IF(AE20="x",1,0) -> 0 | CD20: =IF(AF20="x",1,0) -> 0 | CE20: =IF(AG20="x",1,0) -> 0 | CF20: =IF(AH20="x",1,0) -> 0 | CG20: =IF(AI20="x",1,0) -> 0 | CH20: =IF(AJ20="x",1,0) -> 0 | CI20: =IF(AK20="x",1,0) -> 0 | ... DK20: =IF(BM20="x",1,0) -> 0
B21: 13 | BT21: =CONCATENATE(BP21,BQ21,BR21,BS21) | BZ21: =IF(Z21="x",1,0) -> 0 | CA21: =IF(AB21="x",1,0) -> 0 | CB21: =IF(AD21="x",1,0) -> 0 | CC21: =IF(AE21="x",1,0) -> 0 | CD21: =IF(AF21="x",1,0) -> 0 | CE21: =IF(AG21="x",1,0) -> 0 | CF21: =IF(AH21="x",1,0) -> 0 | CG21: =IF(AI21="x",1,0) -> 0 | CH21: =IF(AJ21="x",1,0) -> 0 | CI21: =IF(AK21="x",1,0) -> 0 | ... DK21: =IF(BM21="x",1,0) -> 0
... B872: 864 | BT872: =CONCATENATE(BP872,BQ872,BR872,BS872) | BZ872: =IF(Z872="x",1,0) -> 0 | CA872: =IF(AB872="x",1,0) -> 0 | CB872: =IF(AD872="x",1,0) -> 0 | CC872: =IF(AE872="x",1,0) -> 0 | CD872: =IF(AF872="x",1,0) -> 0 | CE872: =IF(AG872="x",1,0) -> 0 | CF872: =IF(AH872="x",1,0) -> 0 | CG872: =IF(AI872="x",1,0) -> 0 | CH872: =IF(AJ872="x",1,0) -> 0 | CI872: =IF(AK872="x",1,0) -> 0 | ... DK872: =IF(BM872="x",1,0) -> 0
B873: 865
B874: 866
B875: 867
B876: 868
B877: 869
B878: 870
B879: 871
B880: 872
B881: 873
B882: 874
B883: 875
B884: 876
... B1008: 1000

Sheet DP Count
A1: Nominal Count | D1: Box Reface Count | F1: Pin Reface Count
A2: >70% | B2: =COUNTIF('Prop Drill Pipe Inp Report'!$G$9:$G$1048576,"0><0.7") -> 0 | D2: R1 (Pitting/Galling) | E2: =COUNTIF('Prop Drill Pipe Inp Report'!$AA$9:$AA$1048576,"1") -> 0 | F2: R1 | G2: =COUNTIF('Prop Drill Pipe Inp Report'!$AC$9:$AC$1048576,"1") -> 0
A3: 70-79% | B3: =COUNTIFS('Prop Drill Pipe Inp Report'!$G$9:$G$1048576,"<0.8",'Prop Drill Pipe Inp Report'!$G$9:$G$1048576,">=.7") -> 0 | D3: R2 (Cuts >30%) | E3: =COUNTIF('Prop Drill Pipe Inp Report'!$AA$9:$AA$1048576,"2") -> 0 | F3: R2 | G3: =COUNTIF('Prop Drill Pipe Inp Report'!$AC$9:$AC$1048576,"2") -> 0
A4: 80-90% | B4: =COUNTIFS('Prop Drill Pipe Inp Report'!$G$9:$G$1048576,"<0.91",'Prop Drill Pipe Inp Report'!$G$9:$G$1048576,">=.8") -> 0 | D4: R3 (Out of Length) | E4: =COUNTIF('Prop Drill Pipe Inp Report'!$AA$9:$AA$1048576,"3") -> 0 | F4: R3 | G4: =COUNTIF('Prop Drill Pipe Inp Report'!$AC$9:$AC$1048576,"3") -> 0
A5: 91%+ | B5: =COUNTIF('Prop Drill Pipe Inp Report'!$G$9:$G$1048576,">=0.91") -> 0 | D5: R4 (Handling/Stabbing) | E5: =COUNTIF('Prop Drill Pipe Inp Report'!$AA$9:$AA$1048576,"4") -> 0 | F5: R4 | G5: =COUNTIF('Prop Drill Pipe Inp Report'!$AC$9:$AC$1048576,"4") -> 0

Sheet Data Sheet DP
A1: TOTAL DAMAGES: | B1: =SUM(B2:B13) -> 0 | I1: Joints with Repairs | J1: Joints with DBR
A2: =CONCATENATE(LEFT(TRIM('Prop Drill Pipe Inp Report'!AD8),FIND("~",SUBSTITUTE('Prop Drill Pipe Inp Report'!AD8," ","~",LEN(TRIM('Prop Drill Pipe Inp Report'!AD8))-LEN(SUBSTITUTE(TRIM('Prop Drill Pipe Inp Report'!AD8)," ", ""))))-1),":") -> Damaged Seal: | B2: =C3+D3 -> 0 | C2: Box: | D2: Pin: | I2: =IF('Prop Drill Pipe Inp Report'!AD9="X",1,IF('Prop Drill Pipe Inp Report'!AE9="X",1,IF('Prop Drill Pipe Inp Report'!AF9="X",1,IF('Prop Drill Pipe Inp Report'!AG9="X",1,IF('Prop Drill Pipe Inp Report'!AH9="X",1,IF('Prop Drill Pipe Inp Report'!AI9="X",1,IF('Prop Drill Pipe Inp Report'!AJ9="X",1,IF('Prop Drill Pipe Inp Report'!AK9="X",1,IF('Prop Drill Pipe Inp Report'!AL9="X",1,IF('Prop Drill Pipe Inp Report'!AM9="X",1,IF('Prop Drill Pipe Inp Report'!AN9="X",1,IF('Prop Drill Pipe Inp Report'!AO9="X",1,IF('Prop Drill Pipe Inp Report'!AP9="X",1,IF('Prop Drill Pipe Inp Report'!AQ9="X",1,IF('Prop Drill Pipe Inp Report'!AR9="X",1,IF('Prop Drill Pipe Inp Report'!AS9="X",1,IF('Prop Drill Pipe Inp Report'!AT9="X",1,0))))))))))))))))) -> 0 | J2: =IF('Prop Drill Pipe Inp Report'!AY9="X",1,IF('Prop Drill Pipe Inp Report'!AZ9="X",1,IF('Prop Drill Pipe Inp Report'!BA9="X",1,IF('Prop Drill Pipe Inp Report'!BB9="X",1,IF('Prop Drill Pipe Inp Report'!BC9="X",1,IF('Prop Drill Pipe Inp Report'!BD9="X",1,IF('Prop Drill Pipe Inp Report'!BE9="X",1,IF('Prop Drill Pipe Inp Report'!BF9="X",1,IF('Prop Drill Pipe Inp Report'!BG9="X",1,IF('Prop Drill Pipe Inp Report'!BH9="X",1,IF('Prop Drill Pipe Inp Report'!BI9="X",1,0))))))))))) -> 0
C3: ='Prop Drill Pipe Inp Report'!AD7 -> 0 | D3: ='Prop Drill Pipe Inp Report'!AE7 -> 0 | I3: =IF('Prop Drill Pipe Inp Report'!AD10="X",1,IF('Prop Drill Pipe Inp Report'!AE10="X",1,IF('Prop Drill Pipe Inp Report'!AF10="X",1,IF('Prop Drill Pipe Inp Report'!AG10="X",1,IF('Prop Drill Pipe Inp Report'!AH10="X",1,IF('Prop Drill Pipe Inp Report'!AI10="X",1,IF('Prop Drill Pipe Inp Report'!AJ10="X",1,IF('Prop Drill Pipe Inp Report'!AK10="X",1,IF('Prop Drill Pipe Inp Report'!AL10="X",1,IF('Prop Drill Pipe Inp Report'!AM10="X",1,IF('Prop Drill Pipe Inp Report'!AN10="X",1,IF('Prop Drill Pipe Inp Report'!AO10="X",1,IF('Prop Drill Pipe Inp Report'!AP10="X",1,IF('Prop Drill Pipe Inp Report'!AQ10="X",1,IF('Prop Drill Pipe Inp Report'!AR10="X",1,IF('Prop Drill Pipe Inp Report'!AS10="X",1,IF('Prop Drill Pipe Inp Report'!AT10="X",1,0))))))))))))))))) -> 0 | J3: =IF('Prop Drill Pipe Inp Report'!AY10="X",1,IF('Prop Drill Pipe Inp Report'!AZ10="X",1,IF('Prop Drill Pipe Inp Report'!BA10="X",1,IF('Prop Drill Pipe Inp Report'!BB10="X",1,IF('Prop Drill Pipe Inp Report'!BC10="X",1,IF('Prop Drill Pipe Inp Report'!BD10="X",1,IF('Prop Drill Pipe Inp Report'!BE10="X",1,IF('Prop Drill Pipe Inp Report'!BF10="X",1,IF('Prop Drill Pipe Inp Report'!BG10="X",1,IF('Prop Drill Pipe Inp Report'!BH10="X",1,IF('Prop Drill Pipe Inp Report'!BI10="X",1,0))))))))))) -> 0
A4: =CONCATENATE(LEFT(TRIM('Prop Drill Pipe Inp Report'!AF8),FIND("~",SUBSTITUTE('Prop Drill Pipe Inp Report'!AF8," ","~",LEN(TRIM('Prop Drill Pipe Inp Report'!AF8))-LEN(SUBSTITUTE(TRIM('Prop Drill Pipe Inp Report'!AF8)," ",""))))-1),":") -> Damaged Threads: | B4: =C5+D5 -> 0 | C4: Box: | D4: Pin: | I4: =IF('Prop Drill Pipe Inp Report'!AD11="X",1,IF('Prop Drill Pipe Inp Report'!AE11="X",1,IF('Prop Drill Pipe Inp Report'!AF11="X",1,IF('Prop Drill Pipe Inp Report'!AG11="X",1,IF('Prop Drill Pipe Inp Report'!AH11="X",1,IF('Prop Drill Pipe Inp Report'!AI11="X",1,IF('Prop Drill Pipe Inp Report'!AJ11="X",1,IF('Prop Drill Pipe Inp Report'!AK11="X",1,IF('Prop Drill Pipe Inp Report'!AL11="X",1,IF('Prop Drill Pipe Inp Report'!AM11="X",1,IF('Prop Drill Pipe Inp Report'!AN11="X",1,IF('Prop Drill Pipe Inp Report'!AO11="X",1,IF('Prop Drill Pipe Inp Report'!AP11="X",1,IF('Prop Drill Pipe Inp Report'!AQ11="X",1,IF('Prop Drill Pipe Inp Report'!AR11="X",1,IF('Prop Drill Pipe Inp Report'!AS11="X",1,IF('Prop Drill Pipe Inp Report'!AT11="X",1,0))))))))))))))))) -> 0 | J4: =IF('Prop Drill Pipe Inp Report'!AY11="X",1,IF('Prop Drill Pipe Inp Report'!AZ11="X",1,IF('Prop Drill Pipe Inp Report'!BA11="X",1,IF('Prop Drill Pipe Inp Report'!BB11="X",1,IF('Prop Drill Pipe Inp Report'!BC11="X",1,IF('Prop Drill Pipe Inp Report'!BD11="X",1,IF('Prop Drill Pipe Inp Report'!BE11="X",1,IF('Prop Drill Pipe Inp Report'!BF11="X",1,IF('Prop Drill Pipe Inp Report'!BG11="X",1,IF('Prop Drill Pipe Inp Report'!BH11="X",1,IF('Prop Drill Pipe Inp Report'!BI11="X",1,0))))))))))) -> 0
C5: ='Prop Drill Pipe Inp Report'!AF7 -> 0 | D5: ='Prop Drill Pipe Inp Report'!AG7 -> 0 | I5: =IF('Prop Drill Pipe Inp Report'!AD12="X",1,IF('Prop Drill Pipe Inp Report'!AE12="X",1,IF('Prop Drill Pipe Inp Report'!AF12="X",1,IF('Prop Drill Pipe Inp Report'!AG12="X",1,IF('Prop Drill Pipe Inp Report'!AH12="X",1,IF('Prop Drill Pipe Inp Report'!AI12="X",1,IF('Prop Drill Pipe Inp Report'!AJ12="X",1,IF('Prop Drill Pipe Inp Report'!AK12="X",1,IF('Prop Drill Pipe Inp Report'!AL12="X",1,IF('Prop Drill Pipe Inp Report'!AM12="X",1,IF('Prop Drill Pipe Inp Report'!AN12="X",1,IF('Prop Drill Pipe Inp Report'!AO12="X",1,IF('Prop Drill Pipe Inp Report'!AP12="X",1,IF('Prop Drill Pipe Inp Report'!AQ12="X",1,IF('Prop Drill Pipe Inp Report'!AR12="X",1,IF('Prop Drill Pipe Inp Report'!AS12="X",1,IF('Prop Drill Pipe Inp Report'!AT12="X",1,0))))))))))))))))) -> 0 | J5: =IF('Prop Drill Pipe Inp Report'!AY12="X",1,IF('Prop Drill Pipe Inp Report'!AZ12="X",1,IF('Prop Drill Pipe Inp Report'!BA12="X",1,IF('Prop Drill Pipe Inp Report'!BB12="X",1,IF('Prop Drill Pipe Inp Report'!BC12="X",1,IF('Prop Drill Pipe Inp Report'!BD12="X",1,IF('Prop Drill Pipe Inp Report'!BE12="X",1,IF('Prop Drill Pipe Inp Report'!BF12="X",1,IF('Prop Drill Pipe Inp Report'!BG12="X",1,IF('Prop Drill Pipe Inp Report'!BH12="X",1,IF('Prop Drill Pipe Inp Report'!BI12="X",1,0))))))))))) -> 0
A6: =CONCATENATE(LEFT(TRIM('Prop Drill Pipe Inp Report'!AH8),FIND("~",SUBSTITUTE('Prop Drill Pipe Inp Report'!AH8," ","~",LEN(TRIM('Prop Drill Pipe Inp Report'!AH8))-LEN(SUBSTITUTE(TRIM('Prop Drill Pipe Inp Report'!AH8)," ",""))))-1),":") -> Damaged Torque Shoulder: | B6: =SUM(C7:D7) -> 0 | C6: Box: | D6: Pin: | I6: =IF('Prop Drill Pipe Inp Report'!AD13="X",1,IF('Prop Drill Pipe Inp Report'!AE13="X",1,IF('Prop Drill Pipe Inp Report'!AF13="X",1,IF('Prop Drill Pipe Inp Report'!AG13="X",1,IF('Prop Drill Pipe Inp Report'!AH13="X",1,IF('Prop Drill Pipe Inp Report'!AI13="X",1,IF('Prop Drill Pipe Inp Report'!AJ13="X",1,IF('Prop Drill Pipe Inp Report'!AK13="X",1,IF('Prop Drill Pipe Inp Report'!AL13="X",1,IF('Prop Drill Pipe Inp Report'!AM13="X",1,IF('Prop Drill Pipe Inp Report'!AN13="X",1,IF('Prop Drill Pipe Inp Report'!AO13="X",1,IF('Prop Drill Pipe Inp Report'!AP13="X",1,IF('Prop Drill Pipe Inp Report'!AQ13="X",1,IF('Prop Drill Pipe Inp Report'!AR13="X",1,IF('Prop Drill Pipe Inp Report'!AS13="X",1,IF('Prop Drill Pipe Inp Report'!AT13="X",1,0))))))))))))))))) -> 0 | J6: =IF('Prop Drill Pipe Inp Report'!AY13="X",1,IF('Prop Drill Pipe Inp Report'!AZ13="X",1,IF('Prop Drill Pipe Inp Report'!BA13="X",1,IF('Prop Drill Pipe Inp Report'!BB13="X",1,IF('Prop Drill Pipe Inp Report'!BC13="X",1,IF('Prop Drill Pipe Inp Report'!BD13="X",1,IF('Prop Drill Pipe Inp Report'!BE13="X",1,IF('Prop Drill Pipe Inp Report'!BF13="X",1,IF('Prop Drill Pipe Inp Report'!BG13="X",1,IF('Prop Drill Pipe Inp Report'!BH13="X",1,IF('Prop Drill Pipe Inp Report'!BI13="X",1,0))))))))))) -> 0
C7: ='Prop Drill Pipe Inp Report'!AH7 -> 0 | D7: ='Prop Drill Pipe Inp Report'!AI7 -> 0 | I7: =IF('Prop Drill Pipe Inp Report'!AD14="X",1,IF('Prop Drill Pipe Inp Report'!AE14="X",1,IF('Prop Drill Pipe Inp Report'!AF14="X",1,IF('Prop Drill Pipe Inp Report'!AG14="X",1,IF('Prop Drill Pipe Inp Report'!AH14="X",1,IF('Prop Drill Pipe Inp Report'!AI14="X",1,IF('Prop Drill Pipe Inp Report'!AJ14="X",1,IF('Prop Drill Pipe Inp Report'!AK14="X",1,IF('Prop Drill Pipe Inp Report'!AL14="X",1,IF('Prop Drill Pipe Inp Report'!AM14="X",1,IF('Prop Drill Pipe Inp Report'!AN14="X",1,IF('Prop Drill Pipe Inp Report'!AO14="X",1,IF('Prop Drill Pipe Inp Report'!AP14="X",1,IF('Prop Drill Pipe Inp Report'!AQ14="X",1,IF('Prop Drill Pipe Inp Report'!AR14="X",1,IF('Prop Drill Pipe Inp Report'!AS14="X",1,IF('Prop Drill Pipe Inp Report'!AT14="X",1,0))))))))))))))))) -> 0 | J7: =IF('Prop Drill Pipe Inp Report'!AY14="X",1,IF('Prop Drill Pipe Inp Report'!AZ14="X",1,IF('Prop Drill Pipe Inp Report'!BA14="X",1,IF('Prop Drill Pipe Inp Report'!BB14="X",1,IF('Prop Drill Pipe Inp Report'!BC14="X",1,IF('Prop Drill Pipe Inp Report'!BD14="X",1,IF('Prop Drill Pipe Inp Report'!BE14="X",1,IF('Prop Drill Pipe Inp Report'!BF14="X",1,IF('Prop Drill Pipe Inp Report'!BG14="X",1,IF('Prop Drill Pipe Inp Report'!BH14="X",1,IF('Prop Drill Pipe Inp Report'!BI14="X",1,0))))))))))) -> 0
A8: =CONCATENATE(LEFT(TRIM('Prop Drill Pipe Inp Report'!AJ8),FIND("~",SUBSTITUTE('Prop Drill Pipe Inp Report'!AJ8," ","~",LEN(TRIM('Prop Drill Pipe Inp Report'!AJ8))-LEN(SUBSTITUTE(TRIM('Prop Drill Pipe Inp Report'!AJ8)," ",""))))-1),":") -> Pitted: | B8: =SUM(C9:D9) -> 0 | C8: Box: | D8: Pin: | I8: =IF('Prop Drill Pipe Inp Report'!AD15="X",1,IF('Prop Drill Pipe Inp Report'!AE15="X",1,IF('Prop Drill Pipe Inp Report'!AF15="X",1,IF('Prop Drill Pipe Inp Report'!AG15="X",1,IF('Prop Drill Pipe Inp Report'!AH15="X",1,IF('Prop Drill Pipe Inp Report'!AI15="X",1,IF('Prop Drill Pipe Inp Report'!AJ15="X",1,IF('Prop Drill Pipe Inp Report'!AK15="X",1,IF('Prop Drill Pipe Inp Report'!AL15="X",1,IF('Prop Drill Pipe Inp Report'!AM15="X",1,IF('Prop Drill Pipe Inp Report'!AN15="X",1,IF('Prop Drill Pipe Inp Report'!AO15="X",1,IF('Prop Drill Pipe Inp Report'!AP15="X",1,IF('Prop Drill Pipe Inp Report'!AQ15="X",1,IF('Prop Drill Pipe Inp Report'!AR15="X",1,IF('Prop Drill Pipe Inp Report'!AS15="X",1,IF('Prop Drill Pipe Inp Report'!AT15="X",1,0))))))))))))))))) -> 0 | J8: =IF('Prop Drill Pipe Inp Report'!AY15="X",1,IF('Prop Drill Pipe Inp Report'!AZ15="X",1,IF('Prop Drill Pipe Inp Report'!BA15="X",1,IF('Prop Drill Pipe Inp Report'!BB15="X",1,IF('Prop Drill Pipe Inp Report'!BC15="X",1,IF('Prop Drill Pipe Inp Report'!BD15="X",1,IF('Prop Drill Pipe Inp Report'!BE15="X",1,IF('Prop Drill Pipe Inp Report'!BF15="X",1,IF('Prop Drill Pipe Inp Report'!BG15="X",1,IF('Prop Drill Pipe Inp Report'!BH15="X",1,IF('Prop Drill Pipe Inp Report'!BI15="X",1,0))))))))))) -> 0
C9: ='Prop Drill Pipe Inp Report'!AJ7 -> 0 | D9: ='Prop Drill Pipe Inp Report'!AK7 -> 0 | I9: =IF('Prop Drill Pipe Inp Report'!AD16="X",1,IF('Prop Drill Pipe Inp Report'!AE16="X",1,IF('Prop Drill Pipe Inp Report'!AF16="X",1,IF('Prop Drill Pipe Inp Report'!AG16="X",1,IF('Prop Drill Pipe Inp Report'!AH16="X",1,IF('Prop Drill Pipe Inp Report'!AI16="X",1,IF('Prop Drill Pipe Inp Report'!AJ16="X",1,IF('Prop Drill Pipe Inp Report'!AK16="X",1,IF('Prop Drill Pipe Inp Report'!AL16="X",1,IF('Prop Drill Pipe Inp Report'!AM16="X",1,IF('Prop Drill Pipe Inp Report'!AN16="X",1,IF('Prop Drill Pipe Inp Report'!AO16="X",1,IF('Prop Drill Pipe Inp Report'!AP16="X",1,IF('Prop Drill Pipe Inp Report'!AQ16="X",1,IF('Prop Drill Pipe Inp Report'!AR16="X",1,IF('Prop Drill Pipe Inp Report'!AS16="X",1,IF('Prop Drill Pipe Inp Report'!AT16="X",1,0))))))))))))))))) -> 0 | J9: =IF('Prop Drill Pipe Inp Report'!AY16="X",1,IF('Prop Drill Pipe Inp Report'!AZ16="X",1,IF('Prop Drill Pipe Inp Report'!BA16="X",1,IF('Prop Drill Pipe Inp Report'!BB16="X",1,IF('Prop Drill Pipe Inp Report'!BC16="X",1,IF('Prop Drill Pipe Inp Report'!BD16="X",1,IF('Prop Drill Pipe Inp Report'!BE16="X",1,IF('Prop Drill Pipe Inp Report'!BF16="X",1,IF('Prop Drill Pipe Inp Report'!BG16="X",1,IF('Prop Drill Pipe Inp Report'!BH16="X",1,IF('Prop Drill Pipe Inp Report'!BI16="X",1,0))))))))))) -> 0
A10: =CONCATENATE(LEFT(TRIM('Prop Drill Pipe Inp Report'!AM8),FIND("~",SUBSTITUTE('Prop Drill Pipe Inp Report'!AM8," ","~",LEN(TRIM('Prop Drill Pipe Inp Report'!AM8))-LEN(SUBSTITUTE(TRIM('Prop Drill Pipe Inp Report'!AM8)," ",""))))-1),":") -> Over Refaced: | B10: =SUM(C11:D11) -> 0 | C10: Box: | D10: Pin: | I10: =IF('Prop Drill Pipe Inp Report'!AD17="X",1,IF('Prop Drill Pipe Inp Report'!AE17="X",1,IF('Prop Drill Pipe Inp Report'!AF17="X",1,IF('Prop Drill Pipe Inp Report'!AG17="X",1,IF('Prop Drill Pipe Inp Report'!AH17="X",1,IF('Prop Drill Pipe Inp Report'!AI17="X",1,IF('Prop Drill Pipe Inp Report'!AJ17="X",1,IF('Prop Drill Pipe Inp Report'!AK17="X",1,IF('Prop Drill Pipe Inp Report'!AL17="X",1,IF('Prop Drill Pipe Inp Report'!AM17="X",1,IF('Prop Drill Pipe Inp Report'!AN17="X",1,IF('Prop Drill Pipe Inp Report'!AO17="X",1,IF('Prop Drill Pipe Inp Report'!AP17="X",1,IF('Prop Drill Pipe Inp Report'!AQ17="X",1,IF('Prop Drill Pipe Inp Report'!AR17="X",1,IF('Prop Drill Pipe Inp Report'!AS17="X",1,IF('Prop Drill Pipe Inp Report'!AT17="X",1,0))))))))))))))))) -> 0 | J10: =IF('Prop Drill Pipe Inp Report'!AY17="X",1,IF('Prop Drill Pipe Inp Report'!AZ17="X",1,IF('Prop Drill Pipe Inp Report'!BA17="X",1,IF('Prop Drill Pipe Inp Report'!BB17="X",1,IF('Prop Drill Pipe Inp Report'!BC17="X",1,IF('Prop Drill Pipe Inp Report'!BD17="X",1,IF('Prop Drill Pipe Inp Report'!BE17="X",1,IF('Prop Drill Pipe Inp Report'!BF17="X",1,IF('Prop Drill Pipe Inp Report'!BG17="X",1,IF('Prop Drill Pipe Inp Report'!BH17="X",1,IF('Prop Drill Pipe Inp Report'!BI17="X",1,0))))))))))) -> 0
C11: ='Prop Drill Pipe Inp Report'!AL7 -> 0 | D11: ='Prop Drill Pipe Inp Report'!AM7 -> 0 | I11: =IF('Prop Drill Pipe Inp Report'!AD18="X",1,IF('Prop Drill Pipe Inp Report'!AE18="X",1,IF('Prop Drill Pipe Inp Report'!AF18="X",1,IF('Prop Drill Pipe Inp Report'!AG18="X",1,IF('Prop Drill Pipe Inp Report'!AH18="X",1,IF('Prop Drill Pipe Inp Report'!AI18="X",1,IF('Prop Drill Pipe Inp Report'!AJ18="X",1,IF('Prop Drill Pipe Inp Report'!AK18="X",1,IF('Prop Drill Pipe Inp Report'!AL18="X",1,IF('Prop Drill Pipe Inp Report'!AM18="X",1,IF('Prop Drill Pipe Inp Report'!AN18="X",1,IF('Prop Drill Pipe Inp Report'!AO18="X",1,IF('Prop Drill Pipe Inp Report'!AP18="X",1,IF('Prop Drill Pipe Inp Report'!AQ18="X",1,IF('Prop Drill Pipe Inp Report'!AR18="X",1,IF('Prop Drill Pipe Inp Report'!AS18="X",1,IF('Prop Drill Pipe Inp Report'!AT18="X",1,0))))))))))))))))) -> 0 | J11: =IF('Prop Drill Pipe Inp Report'!AY18="X",1,IF('Prop Drill Pipe Inp Report'!AZ18="X",1,IF('Prop Drill Pipe Inp Report'!BA18="X",1,IF('Prop Drill Pipe Inp Report'!BB18="X",1,IF('Prop Drill Pipe Inp Report'!BC18="X",1,IF('Prop Drill Pipe Inp Report'!BD18="X",1,IF('Prop Drill Pipe Inp Report'!BE18="X",1,IF('Prop Drill Pipe Inp Report'!BF18="X",1,IF('Prop Drill Pipe Inp Report'!BG18="X",1,IF('Prop Drill Pipe Inp Report'!BH18="X",1,IF('Prop Drill Pipe Inp Report'!BI18="X",1,0))))))))))) -> 0
A12: ='Prop Drill Pipe Inp Report'!AN8 -> Bent Tube: | B12: ='Prop Drill Pipe Inp Report'!AN7 -> 0 | I12: =IF('Prop Drill Pipe Inp Report'!AD19="X",1,IF('Prop Drill Pipe Inp Report'!AE19="X",1,IF('Prop Drill Pipe Inp Report'!AF19="X",1,IF('Prop Drill Pipe Inp Report'!AG19="X",1,IF('Prop Drill Pipe Inp Report'!AH19="X",1,IF('Prop Drill Pipe Inp Report'!AI19="X",1,IF('Prop Drill Pipe Inp Report'!AJ19="X",1,IF('Prop Drill Pipe Inp Report'!AK19="X",1,IF('Prop Drill Pipe Inp Report'!AL19="X",1,IF('Prop Drill Pipe Inp Report'!AM19="X",1,IF('Prop Drill Pipe Inp Report'!AN19="X",1,IF('Prop Drill Pipe Inp Report'!AO19="X",1,IF('Prop Drill Pipe Inp Report'!AP19="X",1,IF('Prop Drill Pipe Inp Report'!AQ19="X",1,IF('Prop Drill Pipe Inp Report'!AR19="X",1,IF('Prop Drill Pipe Inp Report'!AS19="X",1,IF('Prop Drill Pipe Inp Report'!AT19="X",1,0))))))))))))))))) -> 0 | J12: =IF('Prop Drill Pipe Inp Report'!AY19="X",1,IF('Prop Drill Pipe Inp Report'!AZ19="X",1,IF('Prop Drill Pipe Inp Report'!BA19="X",1,IF('Prop Drill Pipe Inp Report'!BB19="X",1,IF('Prop Drill Pipe Inp Report'!BC19="X",1,IF('Prop Drill Pipe Inp Report'!BD19="X",1,IF('Prop Drill Pipe Inp Report'!BE19="X",1,IF('Prop Drill Pipe Inp Report'!BF19="X",1,IF('Prop Drill Pipe Inp Report'!BG19="X",1,IF('Prop Drill Pipe Inp Report'!BH19="X",1,IF('Prop Drill Pipe Inp Report'!BI19="X",1,0))))))))))) -> 0
A13: ='Prop Drill Pipe Inp Report'!AO8 -> Other Damage: | B13: ='Prop Drill Pipe Inp Report'!AO7 -> 0 | I13: =IF('Prop Drill Pipe Inp Report'!AD20="X",1,IF('Prop Drill Pipe Inp Report'!AE20="X",1,IF('Prop Drill Pipe Inp Report'!AF20="X",1,IF('Prop Drill Pipe Inp Report'!AG20="X",1,IF('Prop Drill Pipe Inp Report'!AH20="X",1,IF('Prop Drill Pipe Inp Report'!AI20="X",1,IF('Prop Drill Pipe Inp Report'!AJ20="X",1,IF('Prop Drill Pipe Inp Report'!AK20="X",1,IF('Prop Drill Pipe Inp Report'!AL20="X",1,IF('Prop Drill Pipe Inp Report'!AM20="X",1,IF('Prop Drill Pipe Inp Report'!AN20="X",1,IF('Prop Drill Pipe Inp Report'!AO20="X",1,IF('Prop Drill Pipe Inp Report'!AP20="X",1,IF('Prop Drill Pipe Inp Report'!AQ20="X",1,IF('Prop Drill Pipe Inp Report'!AR20="X",1,IF('Prop Drill Pipe Inp Report'!AS20="X",1,IF('Prop Drill Pipe Inp Report'!AT20="X",1,0))))))))))))))))) -> 0 | J13: =IF('Prop Drill Pipe Inp Report'!AY20="X",1,IF('Prop Drill Pipe Inp Report'!AZ20="X",1,IF('Prop Drill Pipe Inp Report'!BA20="X",1,IF('Prop Drill Pipe Inp Report'!BB20="X",1,IF('Prop Drill Pipe Inp Report'!BC20="X",1,IF('Prop Drill Pipe Inp Report'!BD20="X",1,IF('Prop Drill Pipe Inp Report'!BE20="X",1,IF('Prop Drill Pipe Inp Report'!BF20="X",1,IF('Prop Drill Pipe Inp Report'!BG20="X",1,IF('Prop Drill Pipe Inp Report'!BH20="X",1,IF('Prop Drill Pipe Inp Report'!BI20="X",1,0))))))))))) -> 0
A14: ='Prop Drill Pipe Inp Report'!AP8 -> Other Damage: | B14: ='Prop Drill Pipe Inp Report'!AP7 -> 0 | I14: =IF('Prop Drill Pipe Inp Report'!AD21="X",1,IF('Prop Drill Pipe Inp Report'!AE21="X",1,IF('Prop Drill Pipe Inp Report'!AF21="X",1,IF('Prop Drill Pipe Inp Report'!AG21="X",1,IF('Prop Drill Pipe Inp Report'!AH21="X",1,IF('Prop Drill Pipe Inp Report'!AI21="X",1,IF('Prop Drill Pipe Inp Report'!AJ21="X",1,IF('Prop Drill Pipe Inp Report'!AK21="X",1,IF('Prop Drill Pipe Inp Report'!AL21="X",1,IF('Prop Drill Pipe Inp Report'!AM21="X",1,IF('Prop Drill Pipe Inp Report'!AN21="X",1,IF('Prop Drill Pipe Inp Report'!AO21="X",1,IF('Prop Drill Pipe Inp Report'!AP21="X",1,IF('Prop Drill Pipe Inp Report'!AQ21="X",1,IF('Prop Drill Pipe Inp Report'!AR21="X",1,IF('Prop Drill Pipe Inp Report'!AS21="X",1,IF('Prop Drill Pipe Inp Report'!AT21="X",1,0))))))))))))))))) -> 0 | J14: =IF('Prop Drill Pipe Inp Report'!AY21="X",1,IF('Prop Drill Pipe Inp Report'!AZ21="X",1,IF('Prop Drill Pipe Inp Report'!BA21="X",1,IF('Prop Drill Pipe Inp Report'!BB21="X",1,IF('Prop Drill Pipe Inp Report'!BC21="X",1,IF('Prop Drill Pipe Inp Report'!BD21="X",1,IF('Prop Drill Pipe Inp Report'!BE21="X",1,IF('Prop Drill Pipe Inp Report'!BF21="X",1,IF('Prop Drill Pipe Inp Report'!BG21="X",1,IF('Prop Drill Pipe Inp Report'!BH21="X",1,IF('Prop Drill Pipe Inp Report'!BI21="X",1,0))))))))))) -> 0
A15: ='Prop Drill Pipe Inp Report'!AQ8 -> Other Damage: | B15: ='Prop Drill Pipe Inp Report'!AQ7 -> 0 | I15: =IF('Prop Drill Pipe Inp Report'!AD22="X",1,IF('Prop Drill Pipe Inp Report'!AE22="X",1,IF('Prop Drill Pipe Inp Report'!AF22="X",1,IF('Prop Drill Pipe Inp Report'!AG22="X",1,IF('Prop Drill Pipe Inp Report'!AH22="X",1,IF('Prop Drill Pipe Inp Report'!AI22="X",1,IF('Prop Drill Pipe Inp Report'!AJ22="X",1,IF('Prop Drill Pipe Inp Report'!AK22="X",1,IF('Prop Drill Pipe Inp Report'!AL22="X",1,IF('Prop Drill Pipe Inp Report'!AM22="X",1,IF('Prop Drill Pipe Inp Report'!AN22="X",1,IF('Prop Drill Pipe Inp Report'!AO22="X",1,IF('Prop Drill Pipe Inp Report'!AP22="X",1,IF('Prop Drill Pipe Inp Report'!AQ22="X",1,IF('Prop Drill Pipe Inp Report'!AR22="X",1,IF('Prop Drill Pipe Inp Report'!AS22="X",1,IF('Prop Drill Pipe Inp Report'!AT22="X",1,0))))))))))))))))) -> 0 | J15: =IF('Prop Drill Pipe Inp Report'!AY22="X",1,IF('Prop Drill Pipe Inp Report'!AZ22="X",1,IF('Prop Drill Pipe Inp Report'!BA22="X",1,IF('Prop Drill Pipe Inp Report'!BB22="X",1,IF('Prop Drill Pipe Inp Report'!BC22="X",1,IF('Prop Drill Pipe Inp Report'!BD22="X",1,IF('Prop Drill Pipe Inp Report'!BE22="X",1,IF('Prop Drill Pipe Inp Report'!BF22="X",1,IF('Prop Drill Pipe Inp Report'!BG22="X",1,IF('Prop Drill Pipe Inp Report'!BH22="X",1,IF('Prop Drill Pipe Inp Report'!BI22="X",1,0))))))))))) -> 0
A16: ='Prop Drill Pipe Inp Report'!AR8 -> Other Damage: | B16: ='Prop Drill Pipe Inp Report'!AR7 -> 0 | I16: =IF('Prop Drill Pipe Inp Report'!AD23="X",1,IF('Prop Drill Pipe Inp Report'!AE23="X",1,IF('Prop Drill Pipe Inp Report'!AF23="X",1,IF('Prop Drill Pipe Inp Report'!AG23="X",1,IF('Prop Drill Pipe Inp Report'!AH23="X",1,IF('Prop Drill Pipe Inp Report'!AI23="X",1,IF('Prop Drill Pipe Inp Report'!AJ23="X",1,IF('Prop Drill Pipe Inp Report'!AK23="X",1,IF('Prop Drill Pipe Inp Report'!AL23="X",1,IF('Prop Drill Pipe Inp Report'!AM23="X",1,IF('Prop Drill Pipe Inp Report'!AN23="X",1,IF('Prop Drill Pipe Inp Report'!AO23="X",1,IF('Prop Drill Pipe Inp Report'!AP23="X",1,IF('Prop Drill Pipe Inp Report'!AQ23="X",1,IF('Prop Drill Pipe Inp Report'!AR23="X",1,IF('Prop Drill Pipe Inp Report'!AS23="X",1,IF('Prop Drill Pipe Inp Report'!AT23="X",1,0))))))))))))))))) -> 0 | J16: =IF('Prop Drill Pipe Inp Report'!AY23="X",1,IF('Prop Drill Pipe Inp Report'!AZ23="X",1,IF('Prop Drill Pipe Inp Report'!BA23="X",1,IF('Prop Drill Pipe Inp Report'!BB23="X",1,IF('Prop Drill Pipe Inp Report'!BC23="X",1,IF('Prop Drill Pipe Inp Report'!BD23="X",1,IF('Prop Drill Pipe Inp Report'!BE23="X",1,IF('Prop Drill Pipe Inp Report'!BF23="X",1,IF('Prop Drill Pipe Inp Report'!BG23="X",1,IF('Prop Drill Pipe Inp Report'!BH23="X",1,IF('Prop Drill Pipe Inp Report'!BI23="X",1,0))))))))))) -> 0
A17: =CONCATENATE(LEFT(TRIM('Prop Drill Pipe Inp Report'!AS8),FIND("~",SUBSTITUTE('Prop Drill Pipe Inp Report'!AS8," ","~",LEN(TRIM('Prop Drill Pipe Inp Report'!AS8))-LEN(SUBSTITUTE(TRIM('Prop Drill Pipe Inp Report'!AS8)," ", ""))))-1),":") -> Damaged Hardband: | B17: =C18+D18 -> 0 | C17: Box: | D17: Pin: | I17: =IF('Prop Drill Pipe Inp Report'!AD24="X",1,IF('Prop Drill Pipe Inp Report'!AE24="X",1,IF('Prop Drill Pipe Inp Report'!AF24="X",1,IF('Prop Drill Pipe Inp Report'!AG24="X",1,IF('Prop Drill Pipe Inp Report'!AH24="X",1,IF('Prop Drill Pipe Inp Report'!AI24="X",1,IF('Prop Drill Pipe Inp Report'!AJ24="X",1,IF('Prop Drill Pipe Inp Report'!AK24="X",1,IF('Prop Drill Pipe Inp Report'!AL24="X",1,IF('Prop Drill Pipe Inp Report'!AM24="X",1,IF('Prop Drill Pipe Inp Report'!AN24="X",1,IF('Prop Drill Pipe Inp Report'!AO24="X",1,IF('Prop Drill Pipe Inp Report'!AP24="X",1,IF('Prop Drill Pipe Inp Report'!AQ24="X",1,IF('Prop Drill Pipe Inp Report'!AR24="X",1,IF('Prop Drill Pipe Inp Report'!AS24="X",1,IF('Prop Drill Pipe Inp Report'!AT24="X",1,0))))))))))))))))) -> 0 | J17: =IF('Prop Drill Pipe Inp Report'!AY24="X",1,IF('Prop Drill Pipe Inp Report'!AZ24="X",1,IF('Prop Drill Pipe Inp Report'!BA24="X",1,IF('Prop Drill Pipe Inp Report'!BB24="X",1,IF('Prop Drill Pipe Inp Report'!BC24="X",1,IF('Prop Drill Pipe Inp Report'!BD24="X",1,IF('Prop Drill Pipe Inp Report'!BE24="X",1,IF('Prop Drill Pipe Inp Report'!BF24="X",1,IF('Prop Drill Pipe Inp Report'!BG24="X",1,IF('Prop Drill Pipe Inp Report'!BH24="X",1,IF('Prop Drill Pipe Inp Report'!BI24="X",1,0))))))))))) -> 0
C18: ='Prop Drill Pipe Inp Report'!AS7 -> 0 | D18: ='Prop Drill Pipe Inp Report'!AT7 -> 0 | I18: =IF('Prop Drill Pipe Inp Report'!AD25="X",1,IF('Prop Drill Pipe Inp Report'!AE25="X",1,IF('Prop Drill Pipe Inp Report'!AF25="X",1,IF('Prop Drill Pipe Inp Report'!AG25="X",1,IF('Prop Drill Pipe Inp Report'!AH25="X",1,IF('Prop Drill Pipe Inp Report'!AI25="X",1,IF('Prop Drill Pipe Inp Report'!AJ25="X",1,IF('Prop Drill Pipe Inp Report'!AK25="X",1,IF('Prop Drill Pipe Inp Report'!AL25="X",1,IF('Prop Drill Pipe Inp Report'!AM25="X",1,IF('Prop Drill Pipe Inp Report'!AN25="X",1,IF('Prop Drill Pipe Inp Report'!AO25="X",1,IF('Prop Drill Pipe Inp Report'!AP25="X",1,IF('Prop Drill Pipe Inp Report'!AQ25="X",1,IF('Prop Drill Pipe Inp Report'!AR25="X",1,IF('Prop Drill Pipe Inp Report'!AS25="X",1,IF('Prop Drill Pipe Inp Report'!AT25="X",1,0))))))))))))))))) -> 0 | J18: =IF('Prop Drill Pipe Inp Report'!AY25="X",1,IF('Prop Drill Pipe Inp Report'!AZ25="X",1,IF('Prop Drill Pipe Inp Report'!BA25="X",1,IF('Prop Drill Pipe Inp Report'!BB25="X",1,IF('Prop Drill Pipe Inp Report'!BC25="X",1,IF('Prop Drill Pipe Inp Report'!BD25="X",1,IF('Prop Drill Pipe Inp Report'!BE25="X",1,IF('Prop Drill Pipe Inp Report'!BF25="X",1,IF('Prop Drill Pipe Inp Report'!BG25="X",1,IF('Prop Drill Pipe Inp Report'!BH25="X",1,IF('Prop Drill Pipe Inp Report'!BI25="X",1,0))))))))))) -> 0
A19: =CONCATENATE(LEFT(TRIM('Prop Drill Pipe Inp Report'!AY8),FIND("~",SUBSTITUTE('Prop Drill Pipe Inp Report'!AY8," ","~",LEN(TRIM('Prop Drill Pipe Inp Report'!AY8))-LEN(SUBSTITUTE(TRIM('Prop Drill Pipe Inp Report'!AY8)," ",""))))-1),":") -> DBR Hardband: | B19: =SUM(C20:D20) -> 0 | C19: Box: | D19: Pin: | I19: =IF('Prop Drill Pipe Inp Report'!AD26="X",1,IF('Prop Drill Pipe Inp Report'!AE26="X",1,IF('Prop Drill Pipe Inp Report'!AF26="X",1,IF('Prop Drill Pipe Inp Report'!AG26="X",1,IF('Prop Drill Pipe Inp Report'!AH26="X",1,IF('Prop Drill Pipe Inp Report'!AI26="X",1,IF('Prop Drill Pipe Inp Report'!AJ26="X",1,IF('Prop Drill Pipe Inp Report'!AK26="X",1,IF('Prop Drill Pipe Inp Report'!AL26="X",1,IF('Prop Drill Pipe Inp Report'!AM26="X",1,IF('Prop Drill Pipe Inp Report'!AN26="X",1,IF('Prop Drill Pipe Inp Report'!AO26="X",1,IF('Prop Drill Pipe Inp Report'!AP26="X",1,IF('Prop Drill Pipe Inp Report'!AQ26="X",1,IF('Prop Drill Pipe Inp Report'!AR26="X",1,IF('Prop Drill Pipe Inp Report'!AS26="X",1,IF('Prop Drill Pipe Inp Report'!AT26="X",1,0))))))))))))))))) -> 0 | J19: =IF('Prop Drill Pipe Inp Report'!AY26="X",1,IF('Prop Drill Pipe Inp Report'!AZ26="X",1,IF('Prop Drill Pipe Inp Report'!BA26="X",1,IF('Prop Drill Pipe Inp Report'!BB26="X",1,IF('Prop Drill Pipe Inp Report'!BC26="X",1,IF('Prop Drill Pipe Inp Report'!BD26="X",1,IF('Prop Drill Pipe Inp Report'!BE26="X",1,IF('Prop Drill Pipe Inp Report'!BF26="X",1,IF('Prop Drill Pipe Inp Report'!BG26="X",1,IF('Prop Drill Pipe Inp Report'!BH26="X",1,IF('Prop Drill Pipe Inp Report'!BI26="X",1,0))))))))))) -> 0
C20: ='Prop Drill Pipe Inp Report'!AY7 -> 0 | D20: ='Prop Drill Pipe Inp Report'!AZ7 -> 0 | I20: =IF('Prop Drill Pipe Inp Report'!AD27="X",1,IF('Prop Drill Pipe Inp Report'!AE27="X",1,IF('Prop Drill Pipe Inp Report'!AF27="X",1,IF('Prop Drill Pipe Inp Report'!AG27="X",1,IF('Prop Drill Pipe Inp Report'!AH27="X",1,IF('Prop Drill Pipe Inp Report'!AI27="X",1,IF('Prop Drill Pipe Inp Report'!AJ27="X",1,IF('Prop Drill Pipe Inp Report'!AK27="X",1,IF('Prop Drill Pipe Inp Report'!AL27="X",1,IF('Prop Drill Pipe Inp Report'!AM27="X",1,IF('Prop Drill Pipe Inp Report'!AN27="X",1,IF('Prop Drill Pipe Inp Report'!AO27="X",1,IF('Prop Drill Pipe Inp Report'!AP27="X",1,IF('Prop Drill Pipe Inp Report'!AQ27="X",1,IF('Prop Drill Pipe Inp Report'!AR27="X",1,IF('Prop Drill Pipe Inp Report'!AS27="X",1,IF('Prop Drill Pipe Inp Report'!AT27="X",1,0))))))))))))))))) -> 0 | J20: =IF('Prop Drill Pipe Inp Report'!AY27="X",1,IF('Prop Drill Pipe Inp Report'!AZ27="X",1,IF('Prop Drill Pipe Inp Report'!BA27="X",1,IF('Prop Drill Pipe Inp Report'!BB27="X",1,IF('Prop Drill Pipe Inp Report'!BC27="X",1,IF('Prop Drill Pipe Inp Report'!BD27="X",1,IF('Prop Drill Pipe Inp Report'!BE27="X",1,IF('Prop Drill Pipe Inp Report'!BF27="X",1,IF('Prop Drill Pipe Inp Report'!BG27="X",1,IF('Prop Drill Pipe Inp Report'!BH27="X",1,IF('Prop Drill Pipe Inp Report'!BI27="X",1,0))))))))))) -> 0
A21: =LEFT(TRIM('Prop Drill Pipe Inp Report'!BA8),FIND("~",SUBSTITUTE('Prop Drill Pipe Inp Report'!BA8," ","~",LEN(TRIM('Prop Drill Pipe Inp Report'!BA8))-LEN(SUBSTITUTE(TRIM('Prop Drill Pipe Inp Report'!BA8)," ",""))))-1) -> Minimum Wall | B21: ='Prop Drill Pipe Inp Report'!BA7 -> 0 | I21: =IF('Prop Drill Pipe Inp Report'!AD28="X",1,IF('Prop Drill Pipe Inp Report'!AE28="X",1,IF('Prop Drill Pipe Inp Report'!AF28="X",1,IF('Prop Drill Pipe Inp Report'!AG28="X",1,IF('Prop Drill Pipe Inp Report'!AH28="X",1,IF('Prop Drill Pipe Inp Report'!AI28="X",1,IF('Prop Drill Pipe Inp Report'!AJ28="X",1,IF('Prop Drill Pipe Inp Report'!AK28="X",1,IF('Prop Drill Pipe Inp Report'!AL28="X",1,IF('Prop Drill Pipe Inp Report'!AM28="X",1,IF('Prop Drill Pipe Inp Report'!AN28="X",1,IF('Prop Drill Pipe Inp Report'!AO28="X",1,IF('Prop Drill Pipe Inp Report'!AP28="X",1,IF('Prop Drill Pipe Inp Report'!AQ28="X",1,IF('Prop Drill Pipe Inp Report'!AR28="X",1,IF('Prop Drill Pipe Inp Report'!AS28="X",1,IF('Prop Drill Pipe Inp Report'!AT28="X",1,0))))))))))))))))) -> 0 | J21: =IF('Prop Drill Pipe Inp Report'!AY28="X",1,IF('Prop Drill Pipe Inp Report'!AZ28="X",1,IF('Prop Drill Pipe Inp Report'!BA28="X",1,IF('Prop Drill Pipe Inp Report'!BB28="X",1,IF('Prop Drill Pipe Inp Report'!BC28="X",1,IF('Prop Drill Pipe Inp Report'!BD28="X",1,IF('Prop Drill Pipe Inp Report'!BE28="X",1,IF('Prop Drill Pipe Inp Report'!BF28="X",1,IF('Prop Drill Pipe Inp Report'!BG28="X",1,IF('Prop Drill Pipe Inp Report'!BH28="X",1,IF('Prop Drill Pipe Inp Report'!BI28="X",1,0))))))))))) -> 0
A22: =CONCATENATE(LEFT(TRIM('Prop Drill Pipe Inp Report'!BC8),FIND("~",SUBSTITUTE('Prop Drill Pipe Inp Report'!BC8," ","~",LEN(TRIM('Prop Drill Pipe Inp Report'!BC8))-LEN(SUBSTITUTE(TRIM('Prop Drill Pipe Inp Report'!BC8)," ",""))))-1),":") -> Min Tong: | B22: =SUM(C23:D23) -> 0 | C22: Box: | D22: Pin: | I22: =IF('Prop Drill Pipe Inp Report'!AD29="X",1,IF('Prop Drill Pipe Inp Report'!AE29="X",1,IF('Prop Drill Pipe Inp Report'!AF29="X",1,IF('Prop Drill Pipe Inp Report'!AG29="X",1,IF('Prop Drill Pipe Inp Report'!AH29="X",1,IF('Prop Drill Pipe Inp Report'!AI29="X",1,IF('Prop Drill Pipe Inp Report'!AJ29="X",1,IF('Prop Drill Pipe Inp Report'!AK29="X",1,IF('Prop Drill Pipe Inp Report'!AL29="X",1,IF('Prop Drill Pipe Inp Report'!AM29="X",1,IF('Prop Drill Pipe Inp Report'!AN29="X",1,IF('Prop Drill Pipe Inp Report'!AO29="X",1,IF('Prop Drill Pipe Inp Report'!AP29="X",1,IF('Prop Drill Pipe Inp Report'!AQ29="X",1,IF('Prop Drill Pipe Inp Report'!AR29="X",1,IF('Prop Drill Pipe Inp Report'!AS29="X",1,IF('Prop Drill Pipe Inp Report'!AT29="X",1,0))))))))))))))))) -> 0 | J22: =IF('Prop Drill Pipe Inp Report'!AY29="X",1,IF('Prop Drill Pipe Inp Report'!AZ29="X",1,IF('Prop Drill Pipe Inp Report'!BA29="X",1,IF('Prop Drill Pipe Inp Report'!BB29="X",1,IF('Prop Drill Pipe Inp Report'!BC29="X",1,IF('Prop Drill Pipe Inp Report'!BD29="X",1,IF('Prop Drill Pipe Inp Report'!BE29="X",1,IF('Prop Drill Pipe Inp Report'!BF29="X",1,IF('Prop Drill Pipe Inp Report'!BG29="X",1,IF('Prop Drill Pipe Inp Report'!BH29="X",1,IF('Prop Drill Pipe Inp Report'!BI29="X",1,0))))))))))) -> 0
C23: ='Prop Drill Pipe Inp Report'!BB7 -> 0 | D23: ='Prop Drill Pipe Inp Report'!BC7 -> 0 | I23: =IF('Prop Drill Pipe Inp Report'!AD30="X",1,IF('Prop Drill Pipe Inp Report'!AE30="X",1,IF('Prop Drill Pipe Inp Report'!AF30="X",1,IF('Prop Drill Pipe Inp Report'!AG30="X",1,IF('Prop Drill Pipe Inp Report'!AH30="X",1,IF('Prop Drill Pipe Inp Report'!AI30="X",1,IF('Prop Drill Pipe Inp Report'!AJ30="X",1,IF('Prop Drill Pipe Inp Report'!AK30="X",1,IF('Prop Drill Pipe Inp Report'!AL30="X",1,IF('Prop Drill Pipe Inp Report'!AM30="X",1,IF('Prop Drill Pipe Inp Report'!AN30="X",1,IF('Prop Drill Pipe Inp Report'!AO30="X",1,IF('Prop Drill Pipe Inp Report'!AP30="X",1,IF('Prop Drill Pipe Inp Report'!AQ30="X",1,IF('Prop Drill Pipe Inp Report'!AR30="X",1,IF('Prop Drill Pipe Inp Report'!AS30="X",1,IF('Prop Drill Pipe Inp Report'!AT30="X",1,0))))))))))))))))) -> 0 | J23: =IF('Prop Drill Pipe Inp Report'!AY30="X",1,IF('Prop Drill Pipe Inp Report'!AZ30="X",1,IF('Prop Drill Pipe Inp Report'!BA30="X",1,IF('Prop Drill Pipe Inp Report'!BB30="X",1,IF('Prop Drill Pipe Inp Report'!BC30="X",1,IF('Prop Drill Pipe Inp Report'!BD30="X",1,IF('Prop Drill Pipe Inp Report'!BE30="X",1,IF('Prop Drill Pipe Inp Report'!BF30="X",1,IF('Prop Drill Pipe Inp Report'!BG30="X",1,IF('Prop Drill Pipe Inp Report'!BH30="X",1,IF('Prop Drill Pipe Inp Report'!BI30="X",1,0))))))))))) -> 0
A24: =CONCATENATE(LEFT(TRIM('Prop Drill Pipe Inp Report'!BD8),FIND("~",SUBSTITUTE('Prop Drill Pipe Inp Report'!BD8," ","~",LEN(TRIM('Prop Drill Pipe Inp Report'!BD8))-LEN(SUBSTITUTE(TRIM('Prop Drill Pipe Inp Report'!BD8)," ",""))))-1),":") -> Min Seal: | B24: =SUM(C25:D25) -> 0 | C24: Box: | D24: Pin: | I24: =IF('Prop Drill Pipe Inp Report'!AD31="X",1,IF('Prop Drill Pipe Inp Report'!AE31="X",1,IF('Prop Drill Pipe Inp Report'!AF31="X",1,IF('Prop Drill Pipe Inp Report'!AG31="X",1,IF('Prop Drill Pipe Inp Report'!AH31="X",1,IF('Prop Drill Pipe Inp Report'!AI31="X",1,IF('Prop Drill Pipe Inp Report'!AJ31="X",1,IF('Prop Drill Pipe Inp Report'!AK31="X",1,IF('Prop Drill Pipe Inp Report'!AL31="X",1,IF('Prop Drill Pipe Inp Report'!AM31="X",1,IF('Prop Drill Pipe Inp Report'!AN31="X",1,IF('Prop Drill Pipe Inp Report'!AO31="X",1,IF('Prop Drill Pipe Inp Report'!AP31="X",1,IF('Prop Drill Pipe Inp Report'!AQ31="X",1,IF('Prop Drill Pipe Inp Report'!AR31="X",1,IF('Prop Drill Pipe Inp Report'!AS31="X",1,IF('Prop Drill Pipe Inp Report'!AT31="X",1,0))))))))))))))))) -> 0 | J24: =IF('Prop Drill Pipe Inp Report'!AY31="X",1,IF('Prop Drill Pipe Inp Report'!AZ31="X",1,IF('Prop Drill Pipe Inp Report'!BA31="X",1,IF('Prop Drill Pipe Inp Report'!BB31="X",1,IF('Prop Drill Pipe Inp Report'!BC31="X",1,IF('Prop Drill Pipe Inp Report'!BD31="X",1,IF('Prop Drill Pipe Inp Report'!BE31="X",1,IF('Prop Drill Pipe Inp Report'!BF31="X",1,IF('Prop Drill Pipe Inp Report'!BG31="X",1,IF('Prop Drill Pipe Inp Report'!BH31="X",1,IF('Prop Drill Pipe Inp Report'!BI31="X",1,0))))))))))) -> 0
C25: ='Prop Drill Pipe Inp Report'!BD7 -> 0 | D25: ='Prop Drill Pipe Inp Report'!BE7 -> 0 | I25: =IF('Prop Drill Pipe Inp Report'!AD32="X",1,IF('Prop Drill Pipe Inp Report'!AE32="X",1,IF('Prop Drill Pipe Inp Report'!AF32="X",1,IF('Prop Drill Pipe Inp Report'!AG32="X",1,IF('Prop Drill Pipe Inp Report'!AH32="X",1,IF('Prop Drill Pipe Inp Report'!AI32="X",1,IF('Prop Drill Pipe Inp Report'!AJ32="X",1,IF('Prop Drill Pipe Inp Report'!AK32="X",1,IF('Prop Drill Pipe Inp Report'!AL32="X",1,IF('Prop Drill Pipe Inp Report'!AM32="X",1,IF('Prop Drill Pipe Inp Report'!AN32="X",1,IF('Prop Drill Pipe Inp Report'!AO32="X",1,IF('Prop Drill Pipe Inp Report'!AP32="X",1,IF('Prop Drill Pipe Inp Report'!AQ32="X",1,IF('Prop Drill Pipe Inp Report'!AR32="X",1,IF('Prop Drill Pipe Inp Report'!AS32="X",1,IF('Prop Drill Pipe Inp Report'!AT32="X",1,0))))))))))))))))) -> 0 | J25: =IF('Prop Drill Pipe Inp Report'!AY32="X",1,IF('Prop Drill Pipe Inp Report'!AZ32="X",1,IF('Prop Drill Pipe Inp Report'!BA32="X",1,IF('Prop Drill Pipe Inp Report'!BB32="X",1,IF('Prop Drill Pipe Inp Report'!BC32="X",1,IF('Prop Drill Pipe Inp Report'!BD32="X",1,IF('Prop Drill Pipe Inp Report'!BE32="X",1,IF('Prop Drill Pipe Inp Report'!BF32="X",1,IF('Prop Drill Pipe Inp Report'!BG32="X",1,IF('Prop Drill Pipe Inp Report'!BH32="X",1,IF('Prop Drill Pipe Inp Report'!BI32="X",1,0))))))))))) -> 0
A26: ='Prop Drill Pipe Inp Report'!BF8 -> Minimum OD: | B26: ='Prop Drill Pipe Inp Report'!BF7 -> 0 | I26: =IF('Prop Drill Pipe Inp Report'!AD33="X",1,IF('Prop Drill Pipe Inp Report'!AE33="X",1,IF('Prop Drill Pipe Inp Report'!AF33="X",1,IF('Prop Drill Pipe Inp Report'!AG33="X",1,IF('Prop Drill Pipe Inp Report'!AH33="X",1,IF('Prop Drill Pipe Inp Report'!AI33="X",1,IF('Prop Drill Pipe Inp Report'!AJ33="X",1,IF('Prop Drill Pipe Inp Report'!AK33="X",1,IF('Prop Drill Pipe Inp Report'!AL33="X",1,IF('Prop Drill Pipe Inp Report'!AM33="X",1,IF('Prop Drill Pipe Inp Report'!AN33="X",1,IF('Prop Drill Pipe Inp Report'!AO33="X",1,IF('Prop Drill Pipe Inp Report'!AP33="X",1,IF('Prop Drill Pipe Inp Report'!AQ33="X",1,IF('Prop Drill Pipe Inp Report'!AR33="X",1,IF('Prop Drill Pipe Inp Report'!AS33="X",1,IF('Prop Drill Pipe Inp Report'!AT33="X",1,0))))))))))))))))) -> 0 | J26: =IF('Prop Drill Pipe Inp Report'!AY33="X",1,IF('Prop Drill Pipe Inp Report'!AZ33="X",1,IF('Prop Drill Pipe Inp Report'!BA33="X",1,IF('Prop Drill Pipe Inp Report'!BB33="X",1,IF('Prop Drill Pipe Inp Report'!BC33="X",1,IF('Prop Drill Pipe Inp Report'!BD33="X",1,IF('Prop Drill Pipe Inp Report'!BE33="X",1,IF('Prop Drill Pipe Inp Report'!BF33="X",1,IF('Prop Drill Pipe Inp Report'!BG33="X",1,IF('Prop Drill Pipe Inp Report'!BH33="X",1,IF('Prop Drill Pipe Inp Report'!BI33="X",1,0))))))))))) -> 0
A27: ='Prop Drill Pipe Inp Report'!BG8 -> Damaged Tube: | B27: ='Prop Drill Pipe Inp Report'!BG7 -> 0 | I27: =IF('Prop Drill Pipe Inp Report'!AD34="X",1,IF('Prop Drill Pipe Inp Report'!AE34="X",1,IF('Prop Drill Pipe Inp Report'!AF34="X",1,IF('Prop Drill Pipe Inp Report'!AG34="X",1,IF('Prop Drill Pipe Inp Report'!AH34="X",1,IF('Prop Drill Pipe Inp Report'!AI34="X",1,IF('Prop Drill Pipe Inp Report'!AJ34="X",1,IF('Prop Drill Pipe Inp Report'!AK34="X",1,IF('Prop Drill Pipe Inp Report'!AL34="X",1,IF('Prop Drill Pipe Inp Report'!AM34="X",1,IF('Prop Drill Pipe Inp Report'!AN34="X",1,IF('Prop Drill Pipe Inp Report'!AO34="X",1,IF('Prop Drill Pipe Inp Report'!AP34="X",1,IF('Prop Drill Pipe Inp Report'!AQ34="X",1,IF('Prop Drill Pipe Inp Report'!AR34="X",1,IF('Prop Drill Pipe Inp Report'!AS34="X",1,IF('Prop Drill Pipe Inp Report'!AT34="X",1,0))))))))))))))))) -> 0 | J27: =IF('Prop Drill Pipe Inp Report'!AY34="X",1,IF('Prop Drill Pipe Inp Report'!AZ34="X",1,IF('Prop Drill Pipe Inp Report'!BA34="X",1,IF('Prop Drill Pipe Inp Report'!BB34="X",1,IF('Prop Drill Pipe Inp Report'!BC34="X",1,IF('Prop Drill Pipe Inp Report'!BD34="X",1,IF('Prop Drill Pipe Inp Report'!BE34="X",1,IF('Prop Drill Pipe Inp Report'!BF34="X",1,IF('Prop Drill Pipe Inp Report'!BG34="X",1,IF('Prop Drill Pipe Inp Report'!BH34="X",1,IF('Prop Drill Pipe Inp Report'!BI34="X",1,0))))))))))) -> 0
A28: ='Prop Drill Pipe Inp Report'!BH8 -> EMI Reject: | B28: ='Prop Drill Pipe Inp Report'!BH7 -> 0 | I28: =IF('Prop Drill Pipe Inp Report'!AD35="X",1,IF('Prop Drill Pipe Inp Report'!AE35="X",1,IF('Prop Drill Pipe Inp Report'!AF35="X",1,IF('Prop Drill Pipe Inp Report'!AG35="X",1,IF('Prop Drill Pipe Inp Report'!AH35="X",1,IF('Prop Drill Pipe Inp Report'!AI35="X",1,IF('Prop Drill Pipe Inp Report'!AJ35="X",1,IF('Prop Drill Pipe Inp Report'!AK35="X",1,IF('Prop Drill Pipe Inp Report'!AL35="X",1,IF('Prop Drill Pipe Inp Report'!AM35="X",1,IF('Prop Drill Pipe Inp Report'!AN35="X",1,IF('Prop Drill Pipe Inp Report'!AO35="X",1,IF('Prop Drill Pipe Inp Report'!AP35="X",1,IF('Prop Drill Pipe Inp Report'!AQ35="X",1,IF('Prop Drill Pipe Inp Report'!AR35="X",1,IF('Prop Drill Pipe Inp Report'!AS35="X",1,IF('Prop Drill Pipe Inp Report'!AT35="X",1,0))))))))))))))))) -> 0 | J28: =IF('Prop Drill Pipe Inp Report'!AY35="X",1,IF('Prop Drill Pipe Inp Report'!AZ35="X",1,IF('Prop Drill Pipe Inp Report'!BA35="X",1,IF('Prop Drill Pipe Inp Report'!BB35="X",1,IF('Prop Drill Pipe Inp Report'!BC35="X",1,IF('Prop Drill Pipe Inp Report'!BD35="X",1,IF('Prop Drill Pipe Inp Report'!BE35="X",1,IF('Prop Drill Pipe Inp Report'!BF35="X",1,IF('Prop Drill Pipe Inp Report'!BG35="X",1,IF('Prop Drill Pipe Inp Report'!BH35="X",1,IF('Prop Drill Pipe Inp Report'!BI35="X",1,0))))))))))) -> 0
A29: ='Prop Drill Pipe Inp Report'!BI8 -> Other: | B29: ='Prop Drill Pipe Inp Report'!BI7 -> 0 | I29: =IF('Prop Drill Pipe Inp Report'!AD36="X",1,IF('Prop Drill Pipe Inp Report'!AE36="X",1,IF('Prop Drill Pipe Inp Report'!AF36="X",1,IF('Prop Drill Pipe Inp Report'!AG36="X",1,IF('Prop Drill Pipe Inp Report'!AH36="X",1,IF('Prop Drill Pipe Inp Report'!AI36="X",1,IF('Prop Drill Pipe Inp Report'!AJ36="X",1,IF('Prop Drill Pipe Inp Report'!AK36="X",1,IF('Prop Drill Pipe Inp Report'!AL36="X",1,IF('Prop Drill Pipe Inp Report'!AM36="X",1,IF('Prop Drill Pipe Inp Report'!AN36="X",1,IF('Prop Drill Pipe Inp Report'!AO36="X",1,IF('Prop Drill Pipe Inp Report'!AP36="X",1,IF('Prop Drill Pipe Inp Report'!AQ36="X",1,IF('Prop Drill Pipe Inp Report'!AR36="X",1,IF('Prop Drill Pipe Inp Report'!AS36="X",1,IF('Prop Drill Pipe Inp Report'!AT36="X",1,0))))))))))))))))) -> 0 | J29: =IF('Prop Drill Pipe Inp Report'!AY36="X",1,IF('Prop Drill Pipe Inp Report'!AZ36="X",1,IF('Prop Drill Pipe Inp Report'!BA36="X",1,IF('Prop Drill Pipe Inp Report'!BB36="X",1,IF('Prop Drill Pipe Inp Report'!BC36="X",1,IF('Prop Drill Pipe Inp Report'!BD36="X",1,IF('Prop Drill Pipe Inp Report'!BE36="X",1,IF('Prop Drill Pipe Inp Report'!BF36="X",1,IF('Prop Drill Pipe Inp Report'!BG36="X",1,IF('Prop Drill Pipe Inp Report'!BH36="X",1,IF('Prop Drill Pipe Inp Report'!BI36="X",1,0))))))))))) -> 0
